<?xml version="1.0" ?>
<robot name="quadruped">
  <material name="chassis_dark">
    <color rgba="0.1 0.1 0.12 1.0"/>
  </material>
  <material name="chassis_accent">
    <color rgba="0.9 0.4 0.04 1.0"/>
  </material>
  <material name="panel_dark">
    <color rgba="0.06 0.06 0.07 1.0"/>
  </material>
  <material name="structural_grey">
    <color rgba="0.42 0.43 0.45 1.0"/>
  </material>
  <material name="actuator_silver">
    <color rgba="0.72 0.73 0.75 1.0"/>
  </material>
  <material name="sensor_black">
    <color rgba="0.04 0.04 0.05 1.0"/>
  </material>
  <material name="lens_glass">
    <color rgba="0.02 0.05 0.09 1.0"/>
  </material>
  <material name="led_green">
    <color rgba="0.15 0.95 0.25 1.0"/>
  </material>
  <material name="led_red">
    <color rgba="0.9 0.08 0.05 1.0"/>
  </material>
  <material name="rubber_black">
    <color rgba="0.05 0.05 0.06 1.0"/>
  </material>
  <link name="base_link">
    <inertial>
      <origin xyz="0.000000 0.000000 0.000000" rpy="0.000000 0.000000 0.000000"/>
      <mass value="3.300000"/>
      <inertia ixx="0.01276000" ixy="0.0" ixz="0.0" iyy="0.04576000" iyz="0.0" izz="0.05500000"/>
    </inertial>
    <visual>
      <origin xyz="0.000000 0.000000 0.000000" rpy="0.000000 0.000000 0.000000"/>
      <geometry>
        <box size="0.400000 0.200000 0.080000"/>
      </geometry>
      <material name="chassis_dark"/>
    </visual>
    <collision>
      <origin xyz="0.000000 0.000000 0.000000" rpy="0.000000 0.000000 0.000000"/>
      <geometry>
        <box size="0.400000 0.200000 0.080000"/>
      </geometry>
    </collision>
    <visual>
      <origin xyz="0.000000 0.000000 0.054000" rpy="0.000000 0.000000 0.000000"/>
      <geometry>
        <box size="0.352000 0.180000 0.028000"/>
      </geometry>
      <material name="chassis_accent"/>
    </visual>
    <visual>
      <origin xyz="0.000000 0.103000 0.000000" rpy="0.000000 0.000000 0.000000"/>
      <geometry>
        <box size="0.328000 0.006000 0.060000"/>
      </geometry>
      <material name="panel_dark"/>
    </visual>
    <visual>
      <origin xyz="-0.100000 0.107000 0.000000" rpy="0.000000 0.000000 0.000000"/>
      <geometry>
        <box size="0.012000 0.002000 0.028000"/>
      </geometry>
      <material name="sensor_black"/>
    </visual>
    <visual>
      <origin xyz="-0.033333 0.107000 0.000000" rpy="0.000000 0.000000 0.000000"/>
      <geometry>
        <box size="0.012000 0.002000 0.028000"/>
      </geometry>
      <material name="sensor_black"/>
    </visual>
    <visual>
      <origin xyz="0.033333 0.107000 0.000000" rpy="0.000000 0.000000 0.000000"/>
      <geometry>
        <box size="0.012000 0.002000 0.028000"/>
      </geometry>
      <material name="sensor_black"/>
    </visual>
    <visual>
      <origin xyz="0.100000 0.107000 0.000000" rpy="0.000000 0.000000 0.000000"/>
      <geometry>
        <box size="0.012000 0.002000 0.028000"/>
      </geometry>
      <material name="sensor_black"/>
    </visual>
    <visual>
      <origin xyz="0.000000 -0.103000 0.000000" rpy="0.000000 0.000000 0.000000"/>
      <geometry>
        <box size="0.328000 0.006000 0.060000"/>
      </geometry>
      <material name="panel_dark"/>
    </visual>
    <visual>
      <origin xyz="-0.100000 -0.107000 0.000000" rpy="0.000000 0.000000 0.000000"/>
      <geometry>
        <box size="0.012000 0.002000 0.028000"/>
      </geometry>
      <material name="sensor_black"/>
    </visual>
    <visual>
      <origin xyz="-0.033333 -0.107000 0.000000" rpy="0.000000 0.000000 0.000000"/>
      <geometry>
        <box size="0.012000 0.002000 0.028000"/>
      </geometry>
      <material name="sensor_black"/>
    </visual>
    <visual>
      <origin xyz="0.033333 -0.107000 0.000000" rpy="0.000000 0.000000 0.000000"/>
      <geometry>
        <box size="0.012000 0.002000 0.028000"/>
      </geometry>
      <material name="sensor_black"/>
    </visual>
    <visual>
      <origin xyz="0.100000 -0.107000 0.000000" rpy="0.000000 0.000000 0.000000"/>
      <geometry>
        <box size="0.012000 0.002000 0.028000"/>
      </geometry>
      <material name="sensor_black"/>
    </visual>
    <visual>
      <origin xyz="0.200000 0.000000 0.004000" rpy="0.000000 0.000000 0.000000"/>
      <geometry>
        <box size="0.022000 0.110000 0.044000"/>
      </geometry>
      <material name="sensor_black"/>
    </visual>
    <visual>
      <origin xyz="0.222000 0.032000 0.004000" rpy="0.000000 0.000000 0.000000"/>
      <geometry>
        <sphere radius="0.007000"/>
      </geometry>
      <material name="lens_glass"/>
    </visual>
    <visual>
      <origin xyz="0.222000 -0.032000 0.004000" rpy="0.000000 0.000000 0.000000"/>
      <geometry>
        <sphere radius="0.007000"/>
      </geometry>
      <material name="lens_glass"/>
    </visual>
    <visual>
      <origin xyz="0.012000 0.000000 0.079000" rpy="0.000000 0.000000 0.000000"/>
      <geometry>
        <cylinder radius="0.032000" length="0.022000"/>
      </geometry>
      <material name="sensor_black"/>
    </visual>
    <visual>
      <origin xyz="0.052000 0.000000 0.072000" rpy="0.000000 0.000000 0.000000"/>
      <geometry>
        <box size="0.022000 0.022000 0.008000"/>
      </geometry>
      <material name="chassis_accent"/>
    </visual>
    <visual>
      <origin xyz="0.144000 0.000000 0.071000" rpy="0.000000 0.000000 0.000000"/>
      <geometry>
        <sphere radius="0.005000"/>
      </geometry>
      <material name="led_green"/>
    </visual>
    <visual>
      <origin xyz="-0.209000 0.000000 0.000000" rpy="0.000000 0.000000 0.000000"/>
      <geometry>
        <box size="0.018000 0.100000 0.040000"/>
      </geometry>
      <material name="panel_dark"/>
    </visual>
    <visual>
      <origin xyz="-0.219000 0.000000 0.000000" rpy="0.000000 0.000000 0.000000"/>
      <geometry>
        <sphere radius="0.006000"/>
      </geometry>
      <material name="led_red"/>
    </visual>
    <visual>
      <origin xyz="-0.060000 0.000000 0.096000" rpy="1.570796 0.000000 0.000000"/>
      <geometry>
        <cylinder radius="0.006000" length="0.100000"/>
      </geometry>
      <material name="panel_dark"/>
    </visual>
    <visual>
      <origin xyz="-0.060000 0.050000 0.082000" rpy="0.000000 0.000000 0.000000"/>
      <geometry>
        <cylinder radius="0.006000" length="0.028000"/>
      </geometry>
      <material name="panel_dark"/>
    </visual>
    <visual>
      <origin xyz="-0.060000 -0.050000 0.082000" rpy="0.000000 0.000000 0.000000"/>
      <geometry>
        <cylinder radius="0.006000" length="0.028000"/>
      </geometry>
      <material name="panel_dark"/>
    </visual>
    <visual>
      <origin xyz="0.160000 0.084000 0.070000" rpy="0.000000 0.000000 0.000000"/>
      <geometry>
        <cylinder radius="0.002800" length="0.004000"/>
      </geometry>
      <material name="actuator_silver"/>
    </visual>
    <visual>
      <origin xyz="0.160000 -0.084000 0.070000" rpy="0.000000 0.000000 0.000000"/>
      <geometry>
        <cylinder radius="0.002800" length="0.004000"/>
      </geometry>
      <material name="actuator_silver"/>
    </visual>
    <visual>
      <origin xyz="-0.160000 0.084000 0.070000" rpy="0.000000 0.000000 0.000000"/>
      <geometry>
        <cylinder radius="0.002800" length="0.004000"/>
      </geometry>
      <material name="actuator_silver"/>
    </visual>
    <visual>
      <origin xyz="-0.160000 -0.084000 0.070000" rpy="0.000000 0.000000 0.000000"/>
      <geometry>
        <cylinder radius="0.002800" length="0.004000"/>
      </geometry>
      <material name="actuator_silver"/>
    </visual>
  </link>
  <joint name="FL_hip_joint" type="revolute">
    <parent link="base_link"/>
    <child link="FL_hip_link"/>
    <origin xyz="0.183000 0.100000 0.000000" rpy="0.000000 0.000000 0.000000"/>
    <axis xyz="1.000000 0.000000 0.000000"/>
    <limit lower="-0.698000" upper="0.698000" velocity="20.000000" effort="10.000000"/>
    <dynamics damping="0.1000" friction="0.0000"/>
  </joint>
  <link name="FL_hip_link">
    <inertial>
      <origin xyz="0.000000 0.031000 0.000000" rpy="0.000000 0.000000 0.000000"/>
      <mass value="0.200000"/>
      <inertia ixx="0.00010907" ixy="0.0" ixz="0.0" iyy="0.00009000" iyz="0.0" izz="0.00010907"/>
    </inertial>
    <visual>
      <origin xyz="0.000000 0.031000 0.000000" rpy="1.570796 0.000000 0.000000"/>
      <geometry>
        <cylinder radius="0.030000" length="0.062000"/>
      </geometry>
      <material name="structural_grey"/>
    </visual>
    <collision>
      <origin xyz="0.000000 0.031000 0.000000" rpy="1.570796 0.000000 0.000000"/>
      <geometry>
        <cylinder radius="0.030000" length="0.062000"/>
      </geometry>
    </collision>
    <visual>
      <origin xyz="0.000000 0.000000 0.000000" rpy="0.000000 1.570796 0.000000"/>
      <geometry>
        <cylinder radius="0.030000" length="0.018000"/>
      </geometry>
      <material name="actuator_silver"/>
    </visual>
    <visual>
      <origin xyz="0.000000 0.000000 0.000000" rpy="0.000000 1.570796 0.000000"/>
      <geometry>
        <cylinder radius="0.034000" length="0.004000"/>
      </geometry>
      <material name="sensor_black"/>
    </visual>
    <visual>
      <origin xyz="0.000000 0.000000 0.000000" rpy="0.000000 1.570796 0.000000"/>
      <geometry>
        <cylinder radius="0.033600" length="0.006000"/>
      </geometry>
      <material name="chassis_accent"/>
    </visual>
  </link>
  <joint name="FL_thigh_joint" type="revolute">
    <parent link="FL_hip_link"/>
    <child link="FL_thigh_link"/>
    <origin xyz="0.000000 0.062000 0.000000" rpy="0.000000 0.000000 0.000000"/>
    <axis xyz="0.000000 1.000000 0.000000"/>
    <limit lower="-1.047000" upper="1.222000" velocity="20.000000" effort="20.000000"/>
    <dynamics damping="0.1000" friction="0.0000"/>
  </joint>
  <link name="FL_thigh_link">
    <inertial>
      <origin xyz="0.000000 0.000000 -0.104500" rpy="0.000000 0.000000 0.000000"/>
      <mass value="0.150000"/>
      <inertia ixx="0.00056416" ixy="0.0" ixz="0.0" iyy="0.00056416" iyz="0.0" izz="0.00003630"/>
    </inertial>
    <visual>
      <origin xyz="0.000000 0.000000 -0.104500" rpy="0.000000 0.000000 0.000000"/>
      <geometry>
        <cylinder radius="0.022000" length="0.209000"/>
      </geometry>
      <material name="structural_grey"/>
    </visual>
    <collision>
      <origin xyz="0.000000 0.000000 -0.104500" rpy="0.000000 0.000000 0.000000"/>
      <geometry>
        <cylinder radius="0.022000" length="0.209000"/>
      </geometry>
    </collision>
    <visual>
      <origin xyz="0.000000 0.000000 0.000000" rpy="1.570796 0.000000 0.000000"/>
      <geometry>
        <cylinder radius="0.042426" length="0.018000"/>
      </geometry>
      <material name="actuator_silver"/>
    </visual>
    <visual>
      <origin xyz="0.000000 0.000000 0.000000" rpy="1.570796 0.000000 0.000000"/>
      <geometry>
        <cylinder radius="0.046426" length="0.004000"/>
      </geometry>
      <material name="sensor_black"/>
    </visual>
    <visual>
      <origin xyz="0.000000 0.000000 0.000000" rpy="1.570796 0.000000 0.000000"/>
      <geometry>
        <cylinder radius="0.024640" length="0.006000"/>
      </geometry>
      <material name="chassis_accent"/>
    </visual>
    <visual>
      <origin xyz="0.000000 0.000000 -0.062700" rpy="0.000000 0.000000 0.000000"/>
      <geometry>
        <cylinder radius="0.025300" length="0.006000"/>
      </geometry>
      <material name="panel_dark"/>
    </visual>
    <visual>
      <origin xyz="0.000000 0.000000 -0.114950" rpy="0.000000 0.000000 0.000000"/>
      <geometry>
        <cylinder radius="0.025300" length="0.006000"/>
      </geometry>
      <material name="panel_dark"/>
    </visual>
    <visual>
      <origin xyz="0.000000 0.000000 -0.167200" rpy="0.000000 0.000000 0.000000"/>
      <geometry>
        <cylinder radius="0.025300" length="0.006000"/>
      </geometry>
      <material name="panel_dark"/>
    </visual>
    <visual>
      <origin xyz="0.025000 0.000000 -0.104500" rpy="0.000000 0.000000 0.000000"/>
      <geometry>
        <box size="0.006000 0.010000 0.171380"/>
      </geometry>
      <material name="panel_dark"/>
    </visual>
  </link>
  <joint name="FL_knee_joint" type="revolute">
    <parent link="FL_thigh_link"/>
    <child link="FL_shin_link"/>
    <origin xyz="0.000000 0.000000 -0.209000" rpy="0.000000 0.000000 0.000000"/>
    <axis xyz="0.000000 1.000000 0.000000"/>
    <limit lower="-2.618000" upper="-0.524000" velocity="20.000000" effort="20.000000"/>
    <dynamics damping="0.1000" friction="0.0000"/>
  </joint>
  <link name="FL_shin_link">
    <inertial>
      <origin xyz="0.000000 0.000000 -0.097500" rpy="0.000000 0.000000 0.000000"/>
      <mass value="0.075000"/>
      <inertia ixx="0.00024246" ixy="0.0" ixz="0.0" iyy="0.00024246" iyz="0.0" izz="0.00000960"/>
    </inertial>
    <visual>
      <origin xyz="0.000000 0.000000 -0.097500" rpy="0.000000 0.000000 0.000000"/>
      <geometry>
        <cylinder radius="0.016000" length="0.195000"/>
      </geometry>
      <material name="structural_grey"/>
    </visual>
    <collision>
      <origin xyz="0.000000 0.000000 -0.097500" rpy="0.000000 0.000000 0.000000"/>
      <geometry>
        <cylinder radius="0.016000" length="0.195000"/>
      </geometry>
    </collision>
    <visual>
      <origin xyz="0.000000 0.000000 0.000000" rpy="1.570796 0.000000 0.000000"/>
      <geometry>
        <cylinder radius="0.042426" length="0.018000"/>
      </geometry>
      <material name="actuator_silver"/>
    </visual>
    <visual>
      <origin xyz="0.000000 0.000000 0.000000" rpy="1.570796 0.000000 0.000000"/>
      <geometry>
        <cylinder radius="0.046426" length="0.004000"/>
      </geometry>
      <material name="sensor_black"/>
    </visual>
    <visual>
      <origin xyz="0.000000 0.000000 0.000000" rpy="1.570796 0.000000 0.000000"/>
      <geometry>
        <cylinder radius="0.017920" length="0.006000"/>
      </geometry>
      <material name="chassis_accent"/>
    </visual>
    <visual>
      <origin xyz="0.000000 0.000000 -0.058500" rpy="0.000000 0.000000 0.000000"/>
      <geometry>
        <cylinder radius="0.018400" length="0.006000"/>
      </geometry>
      <material name="panel_dark"/>
    </visual>
    <visual>
      <origin xyz="0.000000 0.000000 -0.107250" rpy="0.000000 0.000000 0.000000"/>
      <geometry>
        <cylinder radius="0.018400" length="0.006000"/>
      </geometry>
      <material name="panel_dark"/>
    </visual>
    <visual>
      <origin xyz="0.000000 0.000000 -0.156000" rpy="0.000000 0.000000 0.000000"/>
      <geometry>
        <cylinder radius="0.018400" length="0.006000"/>
      </geometry>
      <material name="panel_dark"/>
    </visual>
    <visual>
      <origin xyz="0.019000 0.000000 -0.097500" rpy="0.000000 0.000000 0.000000"/>
      <geometry>
        <box size="0.006000 0.010000 0.159900"/>
      </geometry>
      <material name="panel_dark"/>
    </visual>
    <visual>
      <origin xyz="0.000000 0.000000 -0.185000" rpy="0.000000 0.000000 0.000000"/>
      <geometry>
        <cylinder radius="0.017920" length="0.006000"/>
      </geometry>
      <material name="chassis_accent"/>
    </visual>
  </link>
  <joint name="FL_foot_joint" type="fixed">
    <parent link="FL_shin_link"/>
    <child link="FL_foot_link"/>
    <origin xyz="0.000000 0.000000 -0.195000" rpy="0.000000 0.000000 0.000000"/>
  </joint>
  <link name="FL_foot_link">
    <inertial>
      <origin xyz="0.000000 0.000000 0.000000" rpy="0.000000 0.000000 0.000000"/>
      <mass value="0.025000"/>
      <inertia ixx="0.00000400" ixy="0.0" ixz="0.0" iyy="0.00000400" iyz="0.0" izz="0.00000400"/>
    </inertial>
    <visual>
      <origin xyz="0.000000 0.000000 0.000000" rpy="0.000000 0.000000 0.000000"/>
      <geometry>
        <sphere radius="0.020000"/>
      </geometry>
      <material name="rubber_black"/>
    </visual>
    <collision>
      <origin xyz="0.000000 0.000000 0.000000" rpy="0.000000 0.000000 0.000000"/>
      <geometry>
        <sphere radius="0.020000"/>
      </geometry>
    </collision>
    <visual>
      <origin xyz="0.000000 0.000000 -0.003000" rpy="0.000000 0.000000 0.000000"/>
      <geometry>
        <cylinder radius="0.026000" length="0.010000"/>
      </geometry>
      <material name="rubber_black"/>
    </visual>
  </link>
  <joint name="FR_hip_joint" type="revolute">
    <parent link="base_link"/>
    <child link="FR_hip_link"/>
    <origin xyz="0.183000 -0.100000 0.000000" rpy="0.000000 0.000000 0.000000"/>
    <axis xyz="1.000000 0.000000 0.000000"/>
    <limit lower="-0.698000" upper="0.698000" velocity="20.000000" effort="10.000000"/>
    <dynamics damping="0.1000" friction="0.0000"/>
  </joint>
  <link name="FR_hip_link">
    <inertial>
      <origin xyz="0.000000 -0.031000 0.000000" rpy="0.000000 0.000000 0.000000"/>
      <mass value="0.200000"/>
      <inertia ixx="0.00010907" ixy="0.0" ixz="0.0" iyy="0.00009000" iyz="0.0" izz="0.00010907"/>
    </inertial>
    <visual>
      <origin xyz="0.000000 -0.031000 0.000000" rpy="1.570796 0.000000 0.000000"/>
      <geometry>
        <cylinder radius="0.030000" length="0.062000"/>
      </geometry>
      <material name="structural_grey"/>
    </visual>
    <collision>
      <origin xyz="0.000000 -0.031000 0.000000" rpy="1.570796 0.000000 0.000000"/>
      <geometry>
        <cylinder radius="0.030000" length="0.062000"/>
      </geometry>
    </collision>
    <visual>
      <origin xyz="0.000000 0.000000 0.000000" rpy="0.000000 1.570796 0.000000"/>
      <geometry>
        <cylinder radius="0.030000" length="0.018000"/>
      </geometry>
      <material name="actuator_silver"/>
    </visual>
    <visual>
      <origin xyz="0.000000 0.000000 0.000000" rpy="0.000000 1.570796 0.000000"/>
      <geometry>
        <cylinder radius="0.034000" length="0.004000"/>
      </geometry>
      <material name="sensor_black"/>
    </visual>
    <visual>
      <origin xyz="0.000000 0.000000 0.000000" rpy="0.000000 1.570796 0.000000"/>
      <geometry>
        <cylinder radius="0.033600" length="0.006000"/>
      </geometry>
      <material name="chassis_accent"/>
    </visual>
  </link>
  <joint name="FR_thigh_joint" type="revolute">
    <parent link="FR_hip_link"/>
    <child link="FR_thigh_link"/>
    <origin xyz="0.000000 -0.062000 0.000000" rpy="0.000000 0.000000 0.000000"/>
    <axis xyz="0.000000 1.000000 0.000000"/>
    <limit lower="-1.047000" upper="1.222000" velocity="20.000000" effort="20.000000"/>
    <dynamics damping="0.1000" friction="0.0000"/>
  </joint>
  <link name="FR_thigh_link">
    <inertial>
      <origin xyz="0.000000 0.000000 -0.104500" rpy="0.000000 0.000000 0.000000"/>
      <mass value="0.150000"/>
      <inertia ixx="0.00056416" ixy="0.0" ixz="0.0" iyy="0.00056416" iyz="0.0" izz="0.00003630"/>
    </inertial>
    <visual>
      <origin xyz="0.000000 0.000000 -0.104500" rpy="0.000000 0.000000 0.000000"/>
      <geometry>
        <cylinder radius="0.022000" length="0.209000"/>
      </geometry>
      <material name="structural_grey"/>
    </visual>
    <collision>
      <origin xyz="0.000000 0.000000 -0.104500" rpy="0.000000 0.000000 0.000000"/>
      <geometry>
        <cylinder radius="0.022000" length="0.209000"/>
      </geometry>
    </collision>
    <visual>
      <origin xyz="0.000000 0.000000 0.000000" rpy="1.570796 0.000000 0.000000"/>
      <geometry>
        <cylinder radius="0.042426" length="0.018000"/>
      </geometry>
      <material name="actuator_silver"/>
    </visual>
    <visual>
      <origin xyz="0.000000 0.000000 0.000000" rpy="1.570796 0.000000 0.000000"/>
      <geometry>
        <cylinder radius="0.046426" length="0.004000"/>
      </geometry>
      <material name="sensor_black"/>
    </visual>
    <visual>
      <origin xyz="0.000000 0.000000 0.000000" rpy="1.570796 0.000000 0.000000"/>
      <geometry>
        <cylinder radius="0.024640" length="0.006000"/>
      </geometry>
      <material name="chassis_accent"/>
    </visual>
    <visual>
      <origin xyz="0.000000 0.000000 -0.062700" rpy="0.000000 0.000000 0.000000"/>
      <geometry>
        <cylinder radius="0.025300" length="0.006000"/>
      </geometry>
      <material name="panel_dark"/>
    </visual>
    <visual>
      <origin xyz="0.000000 0.000000 -0.114950" rpy="0.000000 0.000000 0.000000"/>
      <geometry>
        <cylinder radius="0.025300" length="0.006000"/>
      </geometry>
      <material name="panel_dark"/>
    </visual>
    <visual>
      <origin xyz="0.000000 0.000000 -0.167200" rpy="0.000000 0.000000 0.000000"/>
      <geometry>
        <cylinder radius="0.025300" length="0.006000"/>
      </geometry>
      <material name="panel_dark"/>
    </visual>
    <visual>
      <origin xyz="0.025000 0.000000 -0.104500" rpy="0.000000 0.000000 0.000000"/>
      <geometry>
        <box size="0.006000 0.010000 0.171380"/>
      </geometry>
      <material name="panel_dark"/>
    </visual>
  </link>
  <joint name="FR_knee_joint" type="revolute">
    <parent link="FR_thigh_link"/>
    <child link="FR_shin_link"/>
    <origin xyz="0.000000 0.000000 -0.209000" rpy="0.000000 0.000000 0.000000"/>
    <axis xyz="0.000000 1.000000 0.000000"/>
    <limit lower="-2.618000" upper="-0.524000" velocity="20.000000" effort="20.000000"/>
    <dynamics damping="0.1000" friction="0.0000"/>
  </joint>
  <link name="FR_shin_link">
    <inertial>
      <origin xyz="0.000000 0.000000 -0.097500" rpy="0.000000 0.000000 0.000000"/>
      <mass value="0.075000"/>
      <inertia ixx="0.00024246" ixy="0.0" ixz="0.0" iyy="0.00024246" iyz="0.0" izz="0.00000960"/>
    </inertial>
    <visual>
      <origin xyz="0.000000 0.000000 -0.097500" rpy="0.000000 0.000000 0.000000"/>
      <geometry>
        <cylinder radius="0.016000" length="0.195000"/>
      </geometry>
      <material name="structural_grey"/>
    </visual>
    <collision>
      <origin xyz="0.000000 0.000000 -0.097500" rpy="0.000000 0.000000 0.000000"/>
      <geometry>
        <cylinder radius="0.016000" length="0.195000"/>
      </geometry>
    </collision>
    <visual>
      <origin xyz="0.000000 0.000000 0.000000" rpy="1.570796 0.000000 0.000000"/>
      <geometry>
        <cylinder radius="0.042426" length="0.018000"/>
      </geometry>
      <material name="actuator_silver"/>
    </visual>
    <visual>
      <origin xyz="0.000000 0.000000 0.000000" rpy="1.570796 0.000000 0.000000"/>
      <geometry>
        <cylinder radius="0.046426" length="0.004000"/>
      </geometry>
      <material name="sensor_black"/>
    </visual>
    <visual>
      <origin xyz="0.000000 0.000000 0.000000" rpy="1.570796 0.000000 0.000000"/>
      <geometry>
        <cylinder radius="0.017920" length="0.006000"/>
      </geometry>
      <material name="chassis_accent"/>
    </visual>
    <visual>
      <origin xyz="0.000000 0.000000 -0.058500" rpy="0.000000 0.000000 0.000000"/>
      <geometry>
        <cylinder radius="0.018400" length="0.006000"/>
      </geometry>
      <material name="panel_dark"/>
    </visual>
    <visual>
      <origin xyz="0.000000 0.000000 -0.107250" rpy="0.000000 0.000000 0.000000"/>
      <geometry>
        <cylinder radius="0.018400" length="0.006000"/>
      </geometry>
      <material name="panel_dark"/>
    </visual>
    <visual>
      <origin xyz="0.000000 0.000000 -0.156000" rpy="0.000000 0.000000 0.000000"/>
      <geometry>
        <cylinder radius="0.018400" length="0.006000"/>
      </geometry>
      <material name="panel_dark"/>
    </visual>
    <visual>
      <origin xyz="0.019000 0.000000 -0.097500" rpy="0.000000 0.000000 0.000000"/>
      <geometry>
        <box size="0.006000 0.010000 0.159900"/>
      </geometry>
      <material name="panel_dark"/>
    </visual>
    <visual>
      <origin xyz="0.000000 0.000000 -0.185000" rpy="0.000000 0.000000 0.000000"/>
      <geometry>
        <cylinder radius="0.017920" length="0.006000"/>
      </geometry>
      <material name="chassis_accent"/>
    </visual>
  </link>
  <joint name="FR_foot_joint" type="fixed">
    <parent link="FR_shin_link"/>
    <child link="FR_foot_link"/>
    <origin xyz="0.000000 0.000000 -0.195000" rpy="0.000000 0.000000 0.000000"/>
  </joint>
  <link name="FR_foot_link">
    <inertial>
      <origin xyz="0.000000 0.000000 0.000000" rpy="0.000000 0.000000 0.000000"/>
      <mass value="0.025000"/>
      <inertia ixx="0.00000400" ixy="0.0" ixz="0.0" iyy="0.00000400" iyz="0.0" izz="0.00000400"/>
    </inertial>
    <visual>
      <origin xyz="0.000000 0.000000 0.000000" rpy="0.000000 0.000000 0.000000"/>
      <geometry>
        <sphere radius="0.020000"/>
      </geometry>
      <material name="rubber_black"/>
    </visual>
    <collision>
      <origin xyz="0.000000 0.000000 0.000000" rpy="0.000000 0.000000 0.000000"/>
      <geometry>
        <sphere radius="0.020000"/>
      </geometry>
    </collision>
    <visual>
      <origin xyz="0.000000 0.000000 -0.003000" rpy="0.000000 0.000000 0.000000"/>
      <geometry>
        <cylinder radius="0.026000" length="0.010000"/>
      </geometry>
      <material name="rubber_black"/>
    </visual>
  </link>
  <joint name="RL_hip_joint" type="revolute">
    <parent link="base_link"/>
    <child link="RL_hip_link"/>
    <origin xyz="-0.183000 0.100000 0.000000" rpy="0.000000 0.000000 0.000000"/>
    <axis xyz="1.000000 0.000000 0.000000"/>
    <limit lower="-0.698000" upper="0.698000" velocity="20.000000" effort="10.000000"/>
    <dynamics damping="0.1000" friction="0.0000"/>
  </joint>
  <link name="RL_hip_link">
    <inertial>
      <origin xyz="0.000000 0.031000 0.000000" rpy="0.000000 0.000000 0.000000"/>
      <mass value="0.200000"/>
      <inertia ixx="0.00010907" ixy="0.0" ixz="0.0" iyy="0.00009000" iyz="0.0" izz="0.00010907"/>
    </inertial>
    <visual>
      <origin xyz="0.000000 0.031000 0.000000" rpy="1.570796 0.000000 0.000000"/>
      <geometry>
        <cylinder radius="0.030000" length="0.062000"/>
      </geometry>
      <material name="structural_grey"/>
    </visual>
    <collision>
      <origin xyz="0.000000 0.031000 0.000000" rpy="1.570796 0.000000 0.000000"/>
      <geometry>
        <cylinder radius="0.030000" length="0.062000"/>
      </geometry>
    </collision>
    <visual>
      <origin xyz="0.000000 0.000000 0.000000" rpy="0.000000 1.570796 0.000000"/>
      <geometry>
        <cylinder radius="0.030000" length="0.018000"/>
      </geometry>
      <material name="actuator_silver"/>
    </visual>
    <visual>
      <origin xyz="0.000000 0.000000 0.000000" rpy="0.000000 1.570796 0.000000"/>
      <geometry>
        <cylinder radius="0.034000" length="0.004000"/>
      </geometry>
      <material name="sensor_black"/>
    </visual>
    <visual>
      <origin xyz="0.000000 0.000000 0.000000" rpy="0.000000 1.570796 0.000000"/>
      <geometry>
        <cylinder radius="0.033600" length="0.006000"/>
      </geometry>
      <material name="chassis_accent"/>
    </visual>
  </link>
  <joint name="RL_thigh_joint" type="revolute">
    <parent link="RL_hip_link"/>
    <child link="RL_thigh_link"/>
    <origin xyz="0.000000 0.062000 0.000000" rpy="0.000000 0.000000 0.000000"/>
    <axis xyz="0.000000 1.000000 0.000000"/>
    <limit lower="-1.047000" upper="1.222000" velocity="20.000000" effort="20.000000"/>
    <dynamics damping="0.1000" friction="0.0000"/>
  </joint>
  <link name="RL_thigh_link">
    <inertial>
      <origin xyz="0.000000 0.000000 -0.104500" rpy="0.000000 0.000000 0.000000"/>
      <mass value="0.150000"/>
      <inertia ixx="0.00056416" ixy="0.0" ixz="0.0" iyy="0.00056416" iyz="0.0" izz="0.00003630"/>
    </inertial>
    <visual>
      <origin xyz="0.000000 0.000000 -0.104500" rpy="0.000000 0.000000 0.000000"/>
      <geometry>
        <cylinder radius="0.022000" length="0.209000"/>
      </geometry>
      <material name="structural_grey"/>
    </visual>
    <collision>
      <origin xyz="0.000000 0.000000 -0.104500" rpy="0.000000 0.000000 0.000000"/>
      <geometry>
        <cylinder radius="0.022000" length="0.209000"/>
      </geometry>
    </collision>
    <visual>
      <origin xyz="0.000000 0.000000 0.000000" rpy="1.570796 0.000000 0.000000"/>
      <geometry>
        <cylinder radius="0.042426" length="0.018000"/>
      </geometry>
      <material name="actuator_silver"/>
    </visual>
    <visual>
      <origin xyz="0.000000 0.000000 0.000000" rpy="1.570796 0.000000 0.000000"/>
      <geometry>
        <cylinder radius="0.046426" length="0.004000"/>
      </geometry>
      <material name="sensor_black"/>
    </visual>
    <visual>
      <origin xyz="0.000000 0.000000 0.000000" rpy="1.570796 0.000000 0.000000"/>
      <geometry>
        <cylinder radius="0.024640" length="0.006000"/>
      </geometry>
      <material name="chassis_accent"/>
    </visual>
    <visual>
      <origin xyz="0.000000 0.000000 -0.062700" rpy="0.000000 0.000000 0.000000"/>
      <geometry>
        <cylinder radius="0.025300" length="0.006000"/>
      </geometry>
      <material name="panel_dark"/>
    </visual>
    <visual>
      <origin xyz="0.000000 0.000000 -0.114950" rpy="0.000000 0.000000 0.000000"/>
      <geometry>
        <cylinder radius="0.025300" length="0.006000"/>
      </geometry>
      <material name="panel_dark"/>
    </visual>
    <visual>
      <origin xyz="0.000000 0.000000 -0.167200" rpy="0.000000 0.000000 0.000000"/>
      <geometry>
        <cylinder radius="0.025300" length="0.006000"/>
      </geometry>
      <material name="panel_dark"/>
    </visual>
    <visual>
      <origin xyz="0.025000 0.000000 -0.104500" rpy="0.000000 0.000000 0.000000"/>
      <geometry>
        <box size="0.006000 0.010000 0.171380"/>
      </geometry>
      <material name="panel_dark"/>
    </visual>
  </link>
  <joint name="RL_knee_joint" type="revolute">
    <parent link="RL_thigh_link"/>
    <child link="RL_shin_link"/>
    <origin xyz="0.000000 0.000000 -0.209000" rpy="0.000000 0.000000 0.000000"/>
    <axis xyz="0.000000 1.000000 0.000000"/>
    <limit lower="-2.618000" upper="-0.524000" velocity="20.000000" effort="20.000000"/>
    <dynamics damping="0.1000" friction="0.0000"/>
  </joint>
  <link name="RL_shin_link">
    <inertial>
      <origin xyz="0.000000 0.000000 -0.097500" rpy="0.000000 0.000000 0.000000"/>
      <mass value="0.075000"/>
      <inertia ixx="0.00024246" ixy="0.0" ixz="0.0" iyy="0.00024246" iyz="0.0" izz="0.00000960"/>
    </inertial>
    <visual>
      <origin xyz="0.000000 0.000000 -0.097500" rpy="0.000000 0.000000 0.000000"/>
      <geometry>
        <cylinder radius="0.016000" length="0.195000"/>
      </geometry>
      <material name="structural_grey"/>
    </visual>
    <collision>
      <origin xyz="0.000000 0.000000 -0.097500" rpy="0.000000 0.000000 0.000000"/>
      <geometry>
        <cylinder radius="0.016000" length="0.195000"/>
      </geometry>
    </collision>
    <visual>
      <origin xyz="0.000000 0.000000 0.000000" rpy="1.570796 0.000000 0.000000"/>
      <geometry>
        <cylinder radius="0.042426" length="0.018000"/>
      </geometry>
      <material name="actuator_silver"/>
    </visual>
    <visual>
      <origin xyz="0.000000 0.000000 0.000000" rpy="1.570796 0.000000 0.000000"/>
      <geometry>
        <cylinder radius="0.046426" length="0.004000"/>
      </geometry>
      <material name="sensor_black"/>
    </visual>
    <visual>
      <origin xyz="0.000000 0.000000 0.000000" rpy="1.570796 0.000000 0.000000"/>
      <geometry>
        <cylinder radius="0.017920" length="0.006000"/>
      </geometry>
      <material name="chassis_accent"/>
    </visual>
    <visual>
      <origin xyz="0.000000 0.000000 -0.058500" rpy="0.000000 0.000000 0.000000"/>
      <geometry>
        <cylinder radius="0.018400" length="0.006000"/>
      </geometry>
      <material name="panel_dark"/>
    </visual>
    <visual>
      <origin xyz="0.000000 0.000000 -0.107250" rpy="0.000000 0.000000 0.000000"/>
      <geometry>
        <cylinder radius="0.018400" length="0.006000"/>
      </geometry>
      <material name="panel_dark"/>
    </visual>
    <visual>
      <origin xyz="0.000000 0.000000 -0.156000" rpy="0.000000 0.000000 0.000000"/>
      <geometry>
        <cylinder radius="0.018400" length="0.006000"/>
      </geometry>
      <material name="panel_dark"/>
    </visual>
    <visual>
      <origin xyz="0.019000 0.000000 -0.097500" rpy="0.000000 0.000000 0.000000"/>
      <geometry>
        <box size="0.006000 0.010000 0.159900"/>
      </geometry>
      <material name="panel_dark"/>
    </visual>
    <visual>
      <origin xyz="0.000000 0.000000 -0.185000" rpy="0.000000 0.000000 0.000000"/>
      <geometry>
        <cylinder radius="0.017920" length="0.006000"/>
      </geometry>
      <material name="chassis_accent"/>
    </visual>
  </link>
  <joint name="RL_foot_joint" type="fixed">
    <parent link="RL_shin_link"/>
    <child link="RL_foot_link"/>
    <origin xyz="0.000000 0.000000 -0.195000" rpy="0.000000 0.000000 0.000000"/>
  </joint>
  <link name="RL_foot_link">
    <inertial>
      <origin xyz="0.000000 0.000000 0.000000" rpy="0.000000 0.000000 0.000000"/>
      <mass value="0.025000"/>
      <inertia ixx="0.00000400" ixy="0.0" ixz="0.0" iyy="0.00000400" iyz="0.0" izz="0.00000400"/>
    </inertial>
    <visual>
      <origin xyz="0.000000 0.000000 0.000000" rpy="0.000000 0.000000 0.000000"/>
      <geometry>
        <sphere radius="0.020000"/>
      </geometry>
      <material name="rubber_black"/>
    </visual>
    <collision>
      <origin xyz="0.000000 0.000000 0.000000" rpy="0.000000 0.000000 0.000000"/>
      <geometry>
        <sphere radius="0.020000"/>
      </geometry>
    </collision>
    <visual>
      <origin xyz="0.000000 0.000000 -0.003000" rpy="0.000000 0.000000 0.000000"/>
      <geometry>
        <cylinder radius="0.026000" length="0.010000"/>
      </geometry>
      <material name="rubber_black"/>
    </visual>
  </link>
  <joint name="RR_hip_joint" type="revolute">
    <parent link="base_link"/>
    <child link="RR_hip_link"/>
    <origin xyz="-0.183000 -0.100000 0.000000" rpy="0.000000 0.000000 0.000000"/>
    <axis xyz="1.000000 0.000000 0.000000"/>
    <limit lower="-0.698000" upper="0.698000" velocity="20.000000" effort="10.000000"/>
    <dynamics damping="0.1000" friction="0.0000"/>
  </joint>
  <link name="RR_hip_link">
    <inertial>
      <origin xyz="0.000000 -0.031000 0.000000" rpy="0.000000 0.000000 0.000000"/>
      <mass value="0.200000"/>
      <inertia ixx="0.00010907" ixy="0.0" ixz="0.0" iyy="0.00009000" iyz="0.0" izz="0.00010907"/>
    </inertial>
    <visual>
      <origin xyz="0.000000 -0.031000 0.000000" rpy="1.570796 0.000000 0.000000"/>
      <geometry>
        <cylinder radius="0.030000" length="0.062000"/>
      </geometry>
      <material name="structural_grey"/>
    </visual>
    <collision>
      <origin xyz="0.000000 -0.031000 0.000000" rpy="1.570796 0.000000 0.000000"/>
      <geometry>
        <cylinder radius="0.030000" length="0.062000"/>
      </geometry>
    </collision>
    <visual>
      <origin xyz="0.000000 0.000000 0.000000" rpy="0.000000 1.570796 0.000000"/>
      <geometry>
        <cylinder radius="0.030000" length="0.018000"/>
      </geometry>
      <material name="actuator_silver"/>
    </visual>
    <visual>
      <origin xyz="0.000000 0.000000 0.000000" rpy="0.000000 1.570796 0.000000"/>
      <geometry>
        <cylinder radius="0.034000" length="0.004000"/>
      </geometry>
      <material name="sensor_black"/>
    </visual>
    <visual>
      <origin xyz="0.000000 0.000000 0.000000" rpy="0.000000 1.570796 0.000000"/>
      <geometry>
        <cylinder radius="0.033600" length="0.006000"/>
      </geometry>
      <material name="chassis_accent"/>
    </visual>
  </link>
  <joint name="RR_thigh_joint" type="revolute">
    <parent link="RR_hip_link"/>
    <child link="RR_thigh_link"/>
    <origin xyz="0.000000 -0.062000 0.000000" rpy="0.000000 0.000000 0.000000"/>
    <axis xyz="0.000000 1.000000 0.000000"/>
    <limit lower="-1.047000" upper="1.222000" velocity="20.000000" effort="20.000000"/>
    <dynamics damping="0.1000" friction="0.0000"/>
  </joint>
  <link name="RR_thigh_link">
    <inertial>
      <origin xyz="0.000000 0.000000 -0.104500" rpy="0.000000 0.000000 0.000000"/>
      <mass value="0.150000"/>
      <inertia ixx="0.00056416" ixy="0.0" ixz="0.0" iyy="0.00056416" iyz="0.0" izz="0.00003630"/>
    </inertial>
    <visual>
      <origin xyz="0.000000 0.000000 -0.104500" rpy="0.000000 0.000000 0.000000"/>
      <geometry>
        <cylinder radius="0.022000" length="0.209000"/>
      </geometry>
      <material name="structural_grey"/>
    </visual>
    <collision>
      <origin xyz="0.000000 0.000000 -0.104500" rpy="0.000000 0.000000 0.000000"/>
      <geometry>
        <cylinder radius="0.022000" length="0.209000"/>
      </geometry>
    </collision>
    <visual>
      <origin xyz="0.000000 0.000000 0.000000" rpy="1.570796 0.000000 0.000000"/>
      <geometry>
        <cylinder radius="0.042426" length="0.018000"/>
      </geometry>
      <material name="actuator_silver"/>
    </visual>
    <visual>
      <origin xyz="0.000000 0.000000 0.000000" rpy="1.570796 0.000000 0.000000"/>
      <geometry>
        <cylinder radius="0.046426" length="0.004000"/>
      </geometry>
      <material name="sensor_black"/>
    </visual>
    <visual>
      <origin xyz="0.000000 0.000000 0.000000" rpy="1.570796 0.000000 0.000000"/>
      <geometry>
        <cylinder radius="0.024640" length="0.006000"/>
      </geometry>
      <material name="chassis_accent"/>
    </visual>
    <visual>
      <origin xyz="0.000000 0.000000 -0.062700" rpy="0.000000 0.000000 0.000000"/>
      <geometry>
        <cylinder radius="0.025300" length="0.006000"/>
      </geometry>
      <material name="panel_dark"/>
    </visual>
    <visual>
      <origin xyz="0.000000 0.000000 -0.114950" rpy="0.000000 0.000000 0.000000"/>
      <geometry>
        <cylinder radius="0.025300" length="0.006000"/>
      </geometry>
      <material name="panel_dark"/>
    </visual>
    <visual>
      <origin xyz="0.000000 0.000000 -0.167200" rpy="0.000000 0.000000 0.000000"/>
      <geometry>
        <cylinder radius="0.025300" length="0.006000"/>
      </geometry>
      <material name="panel_dark"/>
    </visual>
    <visual>
      <origin xyz="0.025000 0.000000 -0.104500" rpy="0.000000 0.000000 0.000000"/>
      <geometry>
        <box size="0.006000 0.010000 0.171380"/>
      </geometry>
      <material name="panel_dark"/>
    </visual>
  </link>
  <joint name="RR_knee_joint" type="revolute">
    <parent link="RR_thigh_link"/>
    <child link="RR_shin_link"/>
    <origin xyz="0.000000 0.000000 -0.209000" rpy="0.000000 0.000000 0.000000"/>
    <axis xyz="0.000000 1.000000 0.000000"/>
    <limit lower="-2.618000" upper="-0.524000" velocity="20.000000" effort="20.000000"/>
    <dynamics damping="0.1000" friction="0.0000"/>
  </joint>
  <link name="RR_shin_link">
    <inertial>
      <origin xyz="0.000000 0.000000 -0.097500" rpy="0.000000 0.000000 0.000000"/>
      <mass value="0.075000"/>
      <inertia ixx="0.00024246" ixy="0.0" ixz="0.0" iyy="0.00024246" iyz="0.0" izz="0.00000960"/>
    </inertial>
    <visual>
      <origin xyz="0.000000 0.000000 -0.097500" rpy="0.000000 0.000000 0.000000"/>
      <geometry>
        <cylinder radius="0.016000" length="0.195000"/>
      </geometry>
      <material name="structural_grey"/>
    </visual>
    <collision>
      <origin xyz="0.000000 0.000000 -0.097500" rpy="0.000000 0.000000 0.000000"/>
      <geometry>
        <cylinder radius="0.016000" length="0.195000"/>
      </geometry>
    </collision>
    <visual>
      <origin xyz="0.000000 0.000000 0.000000" rpy="1.570796 0.000000 0.000000"/>
      <geometry>
        <cylinder radius="0.042426" length="0.018000"/>
      </geometry>
      <material name="actuator_silver"/>
    </visual>
    <visual>
      <origin xyz="0.000000 0.000000 0.000000" rpy="1.570796 0.000000 0.000000"/>
      <geometry>
        <cylinder radius="0.046426" length="0.004000"/>
      </geometry>
      <material name="sensor_black"/>
    </visual>
    <visual>
      <origin xyz="0.000000 0.000000 0.000000" rpy="1.570796 0.000000 0.000000"/>
      <geometry>
        <cylinder radius="0.017920" length="0.006000"/>
      </geometry>
      <material name="chassis_accent"/>
    </visual>
    <visual>
      <origin xyz="0.000000 0.000000 -0.058500" rpy="0.000000 0.000000 0.000000"/>
      <geometry>
        <cylinder radius="0.018400" length="0.006000"/>
      </geometry>
      <material name="panel_dark"/>
    </visual>
    <visual>
      <origin xyz="0.000000 0.000000 -0.107250" rpy="0.000000 0.000000 0.000000"/>
      <geometry>
        <cylinder radius="0.018400" length="0.006000"/>
      </geometry>
      <material name="panel_dark"/>
    </visual>
    <visual>
      <origin xyz="0.000000 0.000000 -0.156000" rpy="0.000000 0.000000 0.000000"/>
      <geometry>
        <cylinder radius="0.018400" length="0.006000"/>
      </geometry>
      <material name="panel_dark"/>
    </visual>
    <visual>
      <origin xyz="0.019000 0.000000 -0.097500" rpy="0.000000 0.000000 0.000000"/>
      <geometry>
        <box size="0.006000 0.010000 0.159900"/>
      </geometry>
      <material name="panel_dark"/>
    </visual>
    <visual>
      <origin xyz="0.000000 0.000000 -0.185000" rpy="0.000000 0.000000 0.000000"/>
      <geometry>
        <cylinder radius="0.017920" length="0.006000"/>
      </geometry>
      <material name="chassis_accent"/>
    </visual>
  </link>
  <joint name="RR_foot_joint" type="fixed">
    <parent link="RR_shin_link"/>
    <child link="RR_foot_link"/>
    <origin xyz="0.000000 0.000000 -0.195000" rpy="0.000000 0.000000 0.000000"/>
  </joint>
  <link name="RR_foot_link">
    <inertial>
      <origin xyz="0.000000 0.000000 0.000000" rpy="0.000000 0.000000 0.000000"/>
      <mass value="0.025000"/>
      <inertia ixx="0.00000400" ixy="0.0" ixz="0.0" iyy="0.00000400" iyz="0.0" izz="0.00000400"/>
    </inertial>
    <visual>
      <origin xyz="0.000000 0.000000 0.000000" rpy="0.000000 0.000000 0.000000"/>
      <geometry>
        <sphere radius="0.020000"/>
      </geometry>
      <material name="rubber_black"/>
    </visual>
    <collision>
      <origin xyz="0.000000 0.000000 0.000000" rpy="0.000000 0.000000 0.000000"/>
      <geometry>
        <sphere radius="0.020000"/>
      </geometry>
    </collision>
    <visual>
      <origin xyz="0.000000 0.000000 -0.003000" rpy="0.000000 0.000000 0.000000"/>
      <geometry>
        <cylinder radius="0.026000" length="0.010000"/>
      </geometry>
      <material name="rubber_black"/>
    </visual>
  </link>
</robot>
